waiting.....
Process     7 arrived at 0 and left at 7.000000 
waiting.....
Process  2002 arrived at 1 and left at 30.000000 
Process  2005 arrived at 2 and left at 41.000000 
Process  2007 arrived at 3 and left at 46.000000 
Process  2001 arrived at 0 and left at 57.000000 
waiting.....
waiting.....
Process  1008 arrived at 72 and left at 86.000000 
Process  1006 arrived at 71 and left at 97.000000 
waiting.....
waiting.....
Process  1010 arrived at 80 and left at 178.000000 
waiting.....
Process  1011 arrived at 80 and left at 193.000000 
waiting.....
waiting.....
Process  1111 arrived at 80 and left at 232.000000 
waiting.....
Process  3784 arrived at 230 and left at 258.000000 
Process  3777 arrived at 230 and left at 262.000000 
Process  3779 arrived at 230 and left at 267.000000 
Process  3788 arrived at 230 and left at 269.000000 
waiting.....
waiting.....
waiting.....
Process  3795 arrived at 230 and left at 338.000000 
waiting.....
Process  8119 arrived at 350 and left at 371.000000 
waiting.....
Process  8129 arrived at 351 and left at 379.000000 
waiting.....
waiting.....
Process  3772 arrived at 200 and left at 414.000000 
Process  5000 arrived at 400 and left at 417.000000 
Process  5001 arrived at 401 and left at 419.000000 
Process  5002 arrived at 402 and left at 421.000000 
Process  5007 arrived at 403 and left at 425.000000 
waiting.....
Process  4411 arrived at 420 and left at 437.000000 
waiting.....
Process  4421 arrived at 429 and left at 449.000000 
Process  4431 arrived at 438 and left at 460.000000 
waiting.....
Process  4441 arrived at 447 and left at 472.000000 
Process  7999 arrived at 456 and left at 486.000000 
Process  7909 arrived at 458 and left at 500.000000 
Process  7989 arrived at 460 and left at 503.000000 
Process  7979 arrived at 461 and left at 505.000000 
Process  7919 arrived at 461 and left at 506.000000 
waiting.....
Process  7929 arrived at 462 and left at 508.000000 
Process    77 arrived at 501 and left at 548.000000 
waiting.....
waiting.....
Process  4451 arrived at 456 and left at 598.000000 
waiting.....
waiting.....
waiting.....
waiting.....
waiting.....
waiting.....
waiting.....
waiting.....
waiting.....
waiting.....
waiting.....
waiting.....
waiting.....
waiting.....
waiting.....
waiting.....
Process     1 arrived at 500 and left at 928.000000 
waiting.....
waiting.....
waiting.....
waiting.....
waiting.....
waiting.....
waiting.....
waiting.....
waiting.....
waiting.....
Process  9999 arrived at 456 and left at 1028.000000 

 The mean of the data is 74.555556 variance of the data is 12628.558730 
